
<mujocoinclude>
    <body name="stompy_right" pos="0.469 0.5 0" euler="0 0 3.1416">
    <body name="link_right_arm_1_x8_1_inner_1" pos="-0.0766223 0.032495 -0.00775921" quat="0.379928 -0.596368 0.596368 -0.379928">
        <joint name="joint_right_arm_1_x8_1_dof_x8" pos="0 0 0" axis="0 0 1" limited="true" range="-2.0944 2.0944"  />
        <geom type="mesh" rgba="0.972549 0.529412 0.00392157 0.501961" mesh="right_arm_1_x8_1_inner_1" />
        <geom pos="0 0.0155 -0.033" quat="-2.32051e-08 1 0 0" type="mesh" rgba="0.917647 0.917647 0.917647 0.501961" mesh="right_arm_1_shoulder_inner_1" />
        <geom pos="-0.0339787 -0.033 -0.085313" quat="0.707107 0.707107 0 0" type="mesh" rgba="0.917647 0.917647 0.917647 0.501961" mesh="right_arm_1_x8_2_outer_1" />
        <geom pos="0 -0.033 -0.11" quat="-0.707107 0.707107 0 0" type="mesh" rgba="0.768627 0.886275 0.952941 0.501961" mesh="right_arm_1_x8_2_pcb_1" />
        <body name="link_right_arm_1_x8_2_inner_1" pos="0 -0.033 -0.11" quat="0.707107 0.707107 0 0">
          <joint name="joint_right_arm_1_x8_2_dof_x8" pos="0 0 0" axis="0 0 1" limited="true" range="0 1.91986"  />
          <geom type="mesh" rgba="0.972549 0.529412 0.00392157 0.501961" mesh="right_arm_1_x8_2_inner_1" />
          <geom pos="0 0.0155 -0.033" type="mesh" rgba="0.917647 0.917647 0.917647 0.501961" mesh="right_arm_1_shoulder_nontorso_1" />
          <geom pos="-0.036 0.0325 -0.0945" quat="0.5 -0.5 -0.5 -0.5" type="mesh" rgba="0.972549 0.529412 0.00392157 0.501961" mesh="right_arm_1_x6_1_outer_1" />
          <geom pos="0 0.0325 -0.0945" quat="0.5 0.5 -0.5 0.5" type="mesh" rgba="0.980392 0.713726 0.00392157 0.501961" mesh="right_arm_1_x6_1_pcb_1" />
          <body name="link_right_arm_1_x6_1_inner_1" pos="0 0.0325 -0.0945" quat="0.5 -0.5 -0.5 -0.5">
            <joint name="joint_right_arm_1_x6_1_dof_x6" pos="0 0 0" axis="0 0 1" limited="true" range="-1.0472 3.66519"  />
            <geom type="mesh" rgba="0.498039 0.498039 0.498039 0.501961" mesh="right_arm_1_x6_1_inner_1" />
            <geom pos="0.00575 0.00995929 -0.0325" quat="0.5 0 0 -0.866025" type="mesh" rgba="0.972549 0.529412 0.00392157 0.501961" mesh="right_arm_1_elbow_1" />
            <geom pos="-0.000661543 -0.0371458 -0.182823" quat="-0.612372 -0.353553 0.612372 -0.353553" type="mesh" rgba="0.972549 0.529412 0.00392157 0.501961" mesh="right_arm_1_x6_2_outer_1" />
            <geom pos="-0.01625 -0.0281458 -0.214" quat="0.353553 -0.612372 -0.353553 -0.612372" type="mesh" rgba="0.980392 0.713726 0.00392157 0.501961" mesh="right_arm_1_x6_2_pcb_1" />
            <body name="link_right_arm_1_x6_2_inner_1" pos="-0.01625 -0.0281458 -0.214" quat="-0.612372 -0.353553 0.612372 -0.353553">
              <joint name="joint_right_arm_1_x6_2_dof_x6" pos="0 0 0" axis="0 0 1" limited="true" range="-1.5708 1.5708"  />
              <geom type="mesh" rgba="0.498039 0.498039 0.498039 0.501961" mesh="right_arm_1_x6_2_inner_1" />
              <geom pos="0.0115 0 -0.0325" quat="-2.32051e-08 1 0 0" type="mesh" rgba="0.972549 0.529412 0.00392157 0.501961" mesh="right_arm_1_forearm_1" />
              <geom pos="-0.0645 -0.0159099 -0.0534099" quat="-0.5 0.5 -0.5 0.5" type="mesh" rgba="0.972549 0.529412 0.00392157 0.501961" mesh="right_arm_1_x4_1_pcb_1" />
              <geom pos="-0.078 2.87032e-09 -0.0375" quat="-0.5 -0.5 0.5 0.5" type="mesh" rgba="0.768627 0.886275 0.952941 0.501961" mesh="right_arm_1_x4_1_outer_1" />
              <body name="link_right_arm_1_x4_1_inner_1" pos="-0.078 2.87032e-09 -0.0375" quat="0.5 -0.5 0.5 -0.5">
                <joint name="joint_right_arm_1_x4_1_dof_x4" pos="0 0 0" axis="0 0 1" limited="true" range="-3.14159 3.14159"  />
                <geom type="mesh" rgba="0.972549 0.529412 0.00392157 0.501961" mesh="right_arm_1_x4_1_inner_1" />
                <geom pos="-0.0093037 0.00675953 -0.0345" quat="0.99863 0 0 -0.052336" type="mesh" rgba="0.615686 0.811765 0.929412 0.501961" mesh="right_arm_1_hand_1_wrist_1" />
                <geom pos="-0.0187495 -0.0261836 -0.0660901" quat="0.706138 0.706138 -0.0370071 -0.0370071" type="mesh" rgba="0.972549 0.529412 0.00392157 0.501961" mesh="right_arm_1_hand_1_x4_1_pcb_1" />
                <geom pos="-0.00151566 -0.0144206 -0.082" quat="-0.706138 0.706138 -0.0370071 0.0370071" type="mesh" rgba="0.768627 0.886275 0.952941 0.501961" mesh="right_arm_1_hand_1_x4_1_outer_1" />
                <body name="link_right_arm_1_hand_1_x4_1_inner_1" pos="-0.00151566 -0.0144206 -0.082" quat="-0.706138 -0.706138 0.0370071 0.0370071">
                  <joint name="joint_right_arm_1_hand_1_x4_1_dof_x4" pos="0 0 0" axis="0 0 1" limited="true" range="-2.61799 0.523599"  />
                  <geom type="mesh" rgba="0.972549 0.529412 0.00392157 0.501961" mesh="right_arm_1_hand_1_x4_1_inner_1" />
                  <geom pos="-0.0093037 0.00675953 -0.0345" quat="-2.32051e-08 1 0 0" type="mesh" rgba="0.615686 0.811765 0.929412 0.501961" mesh="right_arm_1_hand_1_mount_1" />
                  <geom pos="0.0440795 -0.0839405 -4.20941e-09" quat="-0.32102 0.32102 -0.630037 0.630037" type="mesh" rgba="0.615686 0.811765 0.929412 0.501961" mesh="right_arm_1_hand_1_base_1" />
                  <geom pos="0.0490192 -0.112869 -0.014" quat="-0.32102 -0.32102 0.630037 0.630037" type="mesh" rgba="0.231373 0.380392 0.705882 0.501961" mesh="right_arm_1_hand_1_slide_rail_1" />
                  <geom pos="0.0922279 -0.0670075 0.0212308" quat="-0.32102 -0.32102 0.630037 0.630037" type="mesh" rgba="0.647059 0.647059 0.647059 0.501961" mesh="right_arm_1_hand_1_camera_mount_1" />
                  <geom pos="0.119872 -0.0663878 0.000249996" quat="-0.630037 0.630037 0.32102 -0.32102" type="mesh" rgba="0.615686 0.811765 0.929412 0.501961" mesh="right_arm_1_hand_1_arducam_case_1" />
                  <geom pos="0.0473754 -0.0147545 0.0019099" quat="0.32102 0.32102 -0.630037 -0.630037" type="mesh" rgba="0.972549 0.529412 0.00392157 0.501961" mesh="right_arm_1_hand_1_x4_2_pcb_1" />
                  <geom pos="0.0489455 -0.035561 -0.014" quat="-0.32102 0.32102 -0.630037 0.630037" type="mesh" rgba="0.768627 0.886275 0.952941 0.501961" mesh="right_arm_1_hand_1_x4_2_outer_1" />
                  <body name="stompy_right/camera_focus" pos="0.15 0 0.01">
                    <site pos="0 0 0" size="0.01" type="sphere" name="right_cam_focus" rgba="0 0 1 0"/>
                  </body>
                  <camera name="right_wrist" pos="-0.1 0 0.16" fovy="20" mode="targetbody" target="stompy_right/camera_focus"/>
                  <body name="link_right_arm_1_hand_1_slide_1" pos="0.139251 -0.00228616 -0.014" quat="-0.218508 -0.218508 -0.672498 -0.672499">
                    <joint name="joint_right_arm_1_hand_1_slider_1" pos="0 0 0" axis="0 0 1" type="slide" limited="true" range="-0.034 0"  />
                    <geom type="mesh" rgba="0.917647 0.917647 0.917647 0.501961" mesh="right_arm_1_hand_1_slide_1" />
                    <geom pos="-0.00499 0.01 -0.033" quat="-1.64085e-08 -0.707107 1.64085e-08 -0.707107" type="mesh" rgba="0.647059 0.647059 0.647059 0.501961" mesh="right_arm_1_hand_1_rack_2" />
                    <geom pos="-0.04949 0.01 -0.033" quat="-1.64085e-08 -0.707107 1.64085e-08 -0.707107" type="mesh" rgba="0.647059 0.647059 0.647059 0.501961" mesh="right_arm_1_hand_1_gripper_1" />
                  </body>
                  <body name="link_right_arm_1_hand_1_slide_2" pos="0.0452051 -0.131729 -0.014" quat="0.218508 -0.218508 -0.672499 0.672498">
                    <joint name="joint_right_arm_1_hand_1_slider_2" pos="0 0 0" axis="0 0 1" type="slide" limited="true" range="-0.034 0"  />
                    <geom type="mesh" rgba="0.917647 0.917647 0.917647 0.501961" mesh="right_arm_1_hand_1_slide_2" />
                    <geom pos="-0.00499 -0.01 -0.033" quat="-1.64085e-08 -0.707107 1.64085e-08 -0.707107" type="mesh" rgba="0.647059 0.647059 0.647059 0.501961" mesh="right_arm_1_hand_1_rack_1" />
                    <geom pos="-0.04949 0.01 -0.033" quat="-1.64085e-08 -0.707107 1.64085e-08 -0.707107" type="mesh" rgba="0.647059 0.647059 0.647059 0.501961" mesh="right_arm_1_hand_1_gripper_2" />
                  </body>
                  <!-- <body name="link_right_arm_1_hand_1_x4_2_inner_1" pos="0.0489455 -0.035561 -0.014" quat="-0.32102 -0.32102 0.630037 0.630037">
                    <joint name="joint_right_arm_1_hand_1_x4_2_dof_x4" pos="0 0 0" axis="0 0 1" limited="true" range="-3.14159 3.14159"  />
                    <geom type="mesh" rgba="0.972549 0.529412 0.00392157 0.501961" mesh="right_arm_1_hand_1_x4_2_inner_1" />
                    <geom pos="0.0105058 0.00467747 -0.0345" quat="0.544639 0 0 0.838671" type="mesh" rgba="0.615686 0.811765 0.929412 0.501961" mesh="right_arm_1_hand_1_spur_gear_(26_teeth)_1" />
                  </body> -->
                </body>
              </body>
            </body>
          </body>
        </body>
      </body>
    </body>
</mujocoinclude>
